Workbook

Sheet Sales Data
A1: Order ID | B1: Date | C1: Customer ID | D1: Customer Name | E1: Customer Segment | F1: Region | G1: Sales Channel | H1: Product Category | I1: Product Name | J1: Quantity | K1: Unit Price | L1: Discount % | M1: Total Price | N1: Discount Amount | O1: Total Sales | P1: Cost Per Unit | Q1: Total Cost | R1: Profit | S1: Profit Margin % | T1: Performance | U1: Payment Method | V1: Delivery Status | W1: Delivery Sign | X1: Employee ID | Y1: Employee Name | Z1: Loyalty Status | AA1: Year | AB1: Month | AC1: Quarter
A2: ORD-5000 | B2: 45498 | C2: CUST-1461 | D2: William Schultz | E2: Retail | F2: South | G2: Website | H2: Furniture | I2: Sofa | J2: 2 | K2: 1951.48 | L2: 25 | M2: =J2*K2 -> 3902.96 | N2: =M2*L2% -> 975.74 | O2: =M2-N2 -> 2927.22 | P2: 1264.63 | Q2: =P2*J2 -> 2529.26 | R2: =O2-Q2 -> 397.96 | S2: =R2/Q2 -> 0.15734246 | T2: =IF(S2<=5%,"Low",IF(S2<=15%,"Medium","High")) -> High | U2: Bank Transfer | V2: On-time | W2: =IF(V2="On-time",0,IF('Sales Data'!V2="Delayed",1,2)) -> 0 | X2: EMP-104 | Y2: Brian Evans | Z2: Regular | AA2: =YEAR(B2) -> 2024 | AB2: =TEXT(B2,"mmmm") -> July | AC2: =CHOOSE(ROUNDUP(MONTH(B2)/3,0),"Q1","Q2","Q3","Q4") -> Q3
A3: ORD-5001 | B3: 45406 | C3: CUST-1282 | D3: Lauren King | E3: Online | F3: North | G3: Distributor | H3: Beauty | I3: Conditioner | J3: 14 | K3: 198.3 | L3: 15 | M3: =J3*K3 -> 2776.2 | N3: =M3*L3% -> 416.43 | O3: 2359.77 | P3: 86.75 | Q3: =P3*J3 -> 1214.5 | R3: =O3-Q3 -> 1145.27 | S3: =R3/Q3 -> 0.94299712 | T3: =IF(S3<=5%,"Low",IF(S3<=15%,"Medium","High")) -> High | U3: Credit Card | V3: On-time | W3: =IF(V3="On-time",0,IF('Sales Data'!V3="Delayed",1,2)) -> 0 | X3: EMP-107 | Y3: Lauren Barnes | Z3: New | AA3: 2024 | AB3: =TEXT(B3,"mmmm") -> April | AC3: =CHOOSE(ROUNDUP(MONTH(B3)/3,0),"Q1","Q2","Q3","Q4") -> Q2
A4: ORD-5002 | B4: 44973 | C4: CUST-2997 | D4: Richard Gibson | E4: Retail | F4: East | G4: Website | H4: Appliances | I4: Refrigerator | J4: 17 | K4: 881.48 | L4: 15 | M4: =J4*K4 -> 14985.16 | N4: =M4*L4% -> 2247.774 | O4: =M4-N4 -> 12737.386 | P4: 704.63 | Q4: =P4*J4 -> 11978.71 | R4: =O4-Q4 -> 758.676 | S4: =R4/Q4 -> 0.063335367 | T4: =IF(S4<=5%,"Low",IF(S4<=15%,"Medium","High")) -> Medium | U4: Cash | V4: On-time | W4: =IF(V4="On-time",0,IF('Sales Data'!V4="Delayed",1,2)) -> 0 | X4: EMP-126 | Y4: Edward Garcia | Z4: New | AA4: 2023 | AB4: =TEXT(B4,"mmmm") -> February | AC4: =CHOOSE(ROUNDUP(MONTH(B4)/3,0),"Q1","Q2","Q3","Q4") -> Q1
A5: ORD-5003 | B5: 44852 | C5: CUST-2414 | D5: Kathleen Gonzales | E5: Online | F5: East | G5: Store | H5: Clothing | I5: Shirt | J5: 19 | K5: 1421.02 | L5: 15 | M5: =J5*K5 -> 26999.38 | N5: =M5*L5% -> 4049.907 | O5: =M5-N5 -> 22949.473 | P5: 827.13 | Q5: =P5*J5 -> 15715.47 | R5: =O5-Q5 -> 7234.003 | S5: =R5/Q5 -> 0.46031095 | T5: =IF(S5<=5%,"Low",IF(S5<=15%,"Medium","High")) -> High | U5: Debit Card | V5: On-time | W5: =IF(V5="On-time",0,IF('Sales Data'!V5="Delayed",1,2)) -> 0 | X5: EMP-106 | Y5: Jodi Key | Z5: New | AA5: 2022 | AB5: =TEXT(B5,"mmmm") -> October | AC5: =CHOOSE(ROUNDUP(MONTH(B5)/3,0),"Q1","Q2","Q3","Q4") -> Q4
A6: ORD-5004 | B6: 45048 | C6: CUST-2771 | D6: Judy Howard | E6: Retail | F6: North | G6: App | H6: Electronics | I6: Laptop | J6: 11 | K6: 1944.53 | L6: 0 | M6: =J6*K6 -> 21389.83 | N6: =M6*L6% -> 0 | O6: =M6-N6 -> 21389.83 | P6: 910.78 | Q6: =P6*J6 -> 10018.58 | R6: =O6-Q6 -> 11371.25 | S6: =R6/Q6 -> 1.1350161 | T6: =IF(S6<=5%,"Low",IF(S6<=15%,"Medium","High")) -> High | U6: Cash | V6: Delayed | W6: =IF(V6="On-time",0,IF('Sales Data'!V6="Delayed",1,2)) -> 1 | X6: EMP-119 | Y6: Elizabeth Thompson | Z6: New | AA6: 2023 | AB6: =TEXT(B6,"mmmm") -> May | AC6: =CHOOSE(ROUNDUP(MONTH(B6)/3,0),"Q1","Q2","Q3","Q4") -> Q2
A7: ORD-5005 | B7: 45367 | C7: CUST-1333 | D7: Ashley Pollard | E7: Online | F7: North | G7: Store | H7: Furniture | I7: Table | J7: 18 | K7: 129.54 | L7: 10 | M7: =J7*K7 -> 2331.72 | N7: =M7*L7% -> 233.172 | O7: =M7-N7 -> 2098.548 | P7: 71.42 | Q7: =P7*J7 -> 1285.56 | R7: =O7-Q7 -> 812.988 | S7: =R7/Q7 -> 0.63239989 | T7: =IF(S7<=5%,"Low",IF(S7<=15%,"Medium","High")) -> High | U7: Credit Card | V7: On-time | W7: =IF(V7="On-time",0,IF('Sales Data'!V7="Delayed",1,2)) -> 0 | X7: EMP-119 | Y7: Elizabeth Thompson | Z7: New | AA7: 2024 | AB7: =TEXT(B7,"mmmm") -> March | AC7: =CHOOSE(ROUNDUP(MONTH(B7)/3,0),"Q1","Q2","Q3","Q4") -> Q1
A8: ORD-5006 | B8: 45147 | C8: CUST-1805 | D8: James Shaw | E8: Retail | F8: North | G8: App | H8: Beauty | I8: Lipstick | J8: 5 | K8: 1730.23 | L8: 25 | M8: =J8*K8 -> 8651.15 | N8: =M8*L8% -> 2162.7875 | O8: =M8-N8 -> 6488.3625 | P8: 1245.34 | Q8: =P8*J8 -> 6226.7 | R8: =O8-Q8 -> 261.6625 | S8: =R8/Q8 -> 0.04202266 | T8: =IF(S8<=5%,"Low",IF(S8<=15%,"Medium","High")) -> Low | U8: Debit Card | V8: On-time | W8: =IF(V8="On-time",0,IF('Sales Data'!V8="Delayed",1,2)) -> 0 | X8: EMP-119 | Y8: Elizabeth Thompson | Z8: New | AA8: 2023 | AB8: =TEXT(B8,"mmmm") -> August | AC8: =CHOOSE(ROUNDUP(MONTH(B8)/3,0),"Q1","Q2","Q3","Q4") -> Q3
A9: ORD-5007 | B9: 45623 | C9: CUST-2081 | D9: Jason Randall | E9: Online | F9: West | G9: Website | H9: Clothing | I9: Jeans | J9: 17 | K9: 2413.42 | L9: 20 | M9: =J9*K9 -> 41028.14 | N9: =M9*L9% -> 8205.628 | O9: =M9-N9 -> 32822.512 | P9: 1539.48 | Q9: =P9*J9 -> 26171.16 | R9: =O9-Q9 -> 6651.352 | S9: =R9/Q9 -> 0.25414815 | T9: =IF(S9<=5%,"Low",IF(S9<=15%,"Medium","High")) -> High | U9: Cash | V9: On-time | W9: =IF(V9="On-time",0,IF('Sales Data'!V9="Delayed",1,2)) -> 0 | X9: EMP-117 | Y9: Brandon Hale | Z9: Regular | AA9: 2024 | AB9: =TEXT(B9,"mmmm") -> November | AC9: =CHOOSE(ROUNDUP(MONTH(B9)/3,0),"Q1","Q2","Q3","Q4") -> Q4
A10: ORD-5008 | B10: 45815 | C10: CUST-1686 | D10: Allison Le | E10: Retail | F10: South | G10: Store | H10: Furniture | I10: Desk | J10: 10 | K10: 813.6 | L10: 25 | M10: =J10*K10 -> 8136 | N10: =M10*L10% -> 2034 | O10: =M10-N10 -> 6102 | P10: 534.2 | Q10: =P10*J10 -> 5342 | R10: =O10-Q10 -> 760 | S10: =R10/Q10 -> 0.14226881 | T10: =IF(S10<=5%,"Low",IF(S10<=15%,"Medium","High")) -> Medium | U10: Bank Transfer | V10: On-time | W10: =IF(V10="On-time",0,IF('Sales Data'!V10="Delayed",1,2)) -> 0 | X10: EMP-121 | Y10: Aaron Klein | Z10: New | AA10: 2025 | AB10: =TEXT(B10,"mmmm") -> June | AC10: =CHOOSE(ROUNDUP(MONTH(B10)/3,0),"Q1","Q2","Q3","Q4") -> Q2
A11: ORD-5009 | B11: 45194 | C11: CUST-1458 | D11: Anthony Hicks | E11: Retail | F11: West | G11: Website | H11: Books | I11: Magazine | J11: 3 | K11: 1214.94 | L11: 5 | M11: =J11*K11 -> 3644.82 | N11: =M11*L11% -> 182.241 | O11: =M11-N11 -> 3462.579 | P11: 1010.13 | Q11: =P11*J11 -> 3030.39 | R11: =O11-Q11 -> 432.189 | S11: =R11/Q11 -> 0.14261828 | T11: =IF(S11<=5%,"Low",IF(S11<=15%,"Medium","High")) -> Medium | U11: Mobile Wallet | V11: On-time | W11: =IF(V11="On-time",0,IF('Sales Data'!V11="Delayed",1,2)) -> 0 | X11: EMP-103 | Y11: Maria Mcclain | Z11: Regular | AA11: 2023 | AB11: =TEXT(B11,"mmmm") -> September | AC11: =CHOOSE(ROUNDUP(MONTH(B11)/3,0),"Q1","Q2","Q3","Q4") -> Q3
A12: ORD-5010 | B12: 45512 | C12: CUST-2173 | D12: Ann Nichols | E12: Wholesale | F12: East | G12: Store | H12: Books | I12: Novel | J12: 17 | K12: 1352.44 | L12: 0 | M12: =J12*K12 -> 22991.48 | N12: =M12*L12% -> 0 | O12: =M12-N12 -> 22991.48 | P12: 638.8 | Q12: =P12*J12 -> 10859.6 | R12: =O12-Q12 -> 12131.88 | S12: =R12/Q12 -> 1.1171572 | T12: =IF(S12<=5%,"Low",IF(S12<=15%,"Medium","High")) -> High | U12: Bank Transfer | V12: On-time | W12: =IF(V12="On-time",0,IF('Sales Data'!V12="Delayed",1,2)) -> 0 | X12: EMP-103 | Y12: Maria Mcclain | Z12: VIP | AA12: 2024 | AB12: =TEXT(B12,"mmmm") -> August | AC12: =CHOOSE(ROUNDUP(MONTH(B12)/3,0),"Q1","Q2","Q3","Q4") -> Q3
A13: ORD-5011 | B13: 45544 | C13: CUST-1190 | D13: Charles Hicks | E13: Retail | F13: West | G13: Website | H13: Electronics | I13: Laptop | J13: 11 | K13: 295.86 | L13: 5 | M13: =J13*K13 -> 3254.46 | N13: =M13*L13% -> 162.723 | O13: =M13-N13 -> 3091.737 | P13: 233.96 | Q13: =P13*J13 -> 2573.56 | R13: =O13-Q13 -> 518.177 | S13: =R13/Q13 -> 0.20134638 | T13: =IF(S13<=5%,"Low",IF(S13<=15%,"Medium","High")) -> High | U13: Cash | V13: On-time | W13: =IF(V13="On-time",0,IF('Sales Data'!V13="Delayed",1,2)) -> 0 | X13: EMP-121 | Y13: Aaron Klein | Z13: New | AA13: 2024 | AB13: =TEXT(B13,"mmmm") -> September | AC13: =CHOOSE(ROUNDUP(MONTH(B13)/3,0),"Q1","Q2","Q3","Q4") -> Q3
A14: ORD-5012 | B14: 45362 | C14: CUST-1224 | D14: Zachary Sims | E14: Online | F14: South | G14: Website | H14: Books | I14: Comics | J14: 16 | K14: 241.58 | L14: 15 | M14: =J14*K14 -> 3865.28 | N14: =M14*L14% -> 579.792 | O14: =M14-N14 -> 3285.488 | P14: 188.35 | Q14: =P14*J14 -> 3013.6 | R14: =O14-Q14 -> 271.888 | S14: =R14/Q14 -> 0.090220334 | T14: =IF(S14<=5%,"Low",IF(S14<=15%,"Medium","High")) -> Medium | U14: Credit Card | V14: Delayed | W14: =IF(V14="On-time",0,IF('Sales Data'!V14="Delayed",1,2)) -> 1 | X14: EMP-124 | Y14: Michael Blankenship | Z14: Regular | AA14: 2024 | AB14: =TEXT(B14,"mmmm") -> March | AC14: =CHOOSE(ROUNDUP(MONTH(B14)/3,0),"Q1","Q2","Q3","Q4") -> Q1
A15: ORD-5013 | B15: 44845 | C15: CUST-1551 | D15: Brandi Miller | E15: Wholesale | F15: South | G15: App | H15: Appliances | I15: Oven | J15: 15 | K15: 1344.32 | L15: 0 | M15: =J15*K15 -> 20164.8 | N15: =M15*L15% -> 0 | O15: =M15-N15 -> 20164.8 | P15: 604.55 | Q15: =P15*J15 -> 9068.25 | R15: =O15-Q15 -> 11096.55 | S15: =R15/Q15 -> 1.2236705 | T15: =IF(S15<=5%,"Low",IF(S15<=15%,"Medium","High")) -> High | U15: Credit Card | V15: On-time | W15: =IF(V15="On-time",0,IF('Sales Data'!V15="Delayed",1,2)) -> 0 | X15: EMP-121 | Y15: Aaron Klein | Z15: New | AA15: 2022 | AB15: =TEXT(B15,"mmmm") -> October | AC15: =CHOOSE(ROUNDUP(MONTH(B15)/3,0),"Q1","Q2","Q3","Q4") -> Q4
... A1983: ORD-6981 | B1983: 45618 | C1983: CUST-1204 | D1983: Bailey Clarke | E1983: Retail | F1983: North | G1983: Website | H1983: Electronics | I1983: Headphones | J1983: 18 | K1983: 809.59 | L1983: 5 | M1983: =J1983*K1983 -> 14572.62 | N1983: =M1983*L1983% -> 728.631 | O1983: =M1983-N1983 -> 13843.989 | P1983: 593 | Q1983: =P1983*J1983 -> 10674 | R1983: =O1983-Q1983 -> 3169.989 | S1983: =R1983/Q1983 -> 0.29698229 | T1983: =IF(S1983<=5%,"Low",IF(S1983<=15%,"Medium","High")) -> High | U1983: Credit Card | V1983: Returned | W1983: =IF(V1983="On-time",0,IF('Sales Data'!V1983="Delayed",1,2)) -> 2 | X1983: EMP-101 | Y1983: Peter Harris | Z1983: New | AA1983: 2024 | AB1983: =TEXT(B1983,"mmmm") -> November | AC1983: =CHOOSE(ROUNDUP(MONTH(B1983)/3,0),"Q1","Q2","Q3","Q4") -> Q4
A1984: ORD-6982 | B1984: 45380 | C1984: CUST-2153 | D1984: Samuel Ruiz | E1984: Online | F1984: North | G1984: Store | H1984: Electronics | I1984: Laptop | J1984: 20 | K1984: 1080.96 | L1984: 15 | M1984: =J1984*K1984 -> 21619.2 | N1984: =M1984*L1984% -> 3242.88 | O1984: =M1984-N1984 -> 18376.32 | P1984: 593.57 | Q1984: =P1984*J1984 -> 11871.4 | R1984: =O1984-Q1984 -> 6504.92 | S1984: =R1984/Q1984 -> 0.54794885 | T1984: =IF(S1984<=5%,"Low",IF(S1984<=15%,"Medium","High")) -> High | U1984: Cash | V1984: On-time | W1984: =IF(V1984="On-time",0,IF('Sales Data'!V1984="Delayed",1,2)) -> 0 | X1984: EMP-104 | Y1984: Brian Evans | Z1984: New | AA1984: 2024 | AB1984: =TEXT(B1984,"mmmm") -> March
A1985: ORD-6983 | B1985: 45381 | C1985: CUST-2337 | D1985: Jonathan Long | E1985: Retail | F1985: West | G1985: App | H1985: Clothing | I1985: Jeans | J1985: 9 | K1985: 1216.04 | L1985: 10 | M1985: =J1985*K1985 -> 10944.36 | N1985: =M1985*L1985% -> 1094.436 | O1985: =M1985-N1985 -> 9849.924 | P1985: 1003.08 | Q1985: =P1985*J1985 -> 9027.72 | R1985: =O1985-Q1985 -> 822.204 | S1985: =R1985/Q1985 -> 0.091075487 | T1985: =IF(S1985<=5%,"Low",IF(S1985<=15%,"Medium","High")) -> Medium | U1985: Cash | V1985: On-time | W1985: =IF(V1985="On-time",0,IF('Sales Data'!V1985="Delayed",1,2)) -> 0 | X1985: EMP-117 | Y1985: Brandon Hale | Z1985: Regular | AA1985: 2023 | AB1985: =TEXT(B1985,"mmmm") -> March | AC1985: 1
A1986: ORD-6984 | B1986: 45382 | C1986: CUST-2668 | D1986: Pamela Garcia | E1986: Retail | F1986: North | G1986: Store | H1986: Clothing | I1986: Jeans | J1986: 19 | K1986: 46.17 | L1986: 15 | M1986: =J1986*K1986 -> 877.23 | N1986: =M1986*L1986% -> 131.5845 | O1986: =M1986-N1986 -> 745.6455 | P1986: 31.59 | Q1986: =P1986*J1986 -> 600.21 | R1986: =O1986-Q1986 -> 145.4355 | S1986: =R1986/Q1986 -> 0.24230769 | T1986: =IF(S1986<=5%,"Low",IF(S1986<=15%,"Medium","High")) -> High | U1986: Credit Card | V1986: On-time | W1986: =IF(V1986="On-time",0,IF('Sales Data'!V1986="Delayed",1,2)) -> 0 | X1986: EMP-126 | Y1986: Edward Garcia | Z1986: New | AA1986: 2025 | AB1986: =TEXT(B1986,"mmmm") -> March | AC1986: 2
A1987: ORD-6985 | B1987: 45383 | C1987: CUST-2432 | D1987: Eric Hancock | E1987: Retail | F1987: East | G1987: App | H1987: Electronics | I1987: Smartphone | J1987: 15 | K1987: 1646.05 | L1987: 10 | M1987: =J1987*K1987 -> 24690.75 | N1987: =M1987*L1987% -> 2469.075 | O1987: =M1987-N1987 -> 22221.675 | P1987: 925.43 | Q1987: =P1987*J1987 -> 13881.45 | R1987: =O1987-Q1987 -> 8340.225 | S1987: =R1987/Q1987 -> 0.600818 | T1987: =IF(S1987<=5%,"Low",IF(S1987<=15%,"Medium","High")) -> High | U1987: Debit Card | V1987: On-time | W1987: =IF(V1987="On-time",0,IF('Sales Data'!V1987="Delayed",1,2)) -> 0 | X1987: EMP-110 | Y1987: James Cuevas | Z1987: Regular | AA1987: 2023 | AB1987: =TEXT(B1987,"mmmm") -> April | AC1987: 2
A1988: ORD-6986 | B1988: 45384 | C1988: CUST-1351 | D1988: Michael Spence | E1988: Retail | F1988: North | G1988: Website | H1988: Furniture | I1988: Sofa | J1988: 18 | K1988: 1289.24 | L1988: 15 | M1988: =J1988*K1988 -> 23206.32 | N1988: =M1988*L1988% -> 3480.948 | O1988: =M1988-N1988 -> 19725.372 | P1988: 1018.77 | Q1988: =P1988*J1988 -> 18337.86 | R1988: =O1988-Q1988 -> 1387.512 | S1988: =R1988/Q1988 -> 0.075663791 | T1988: =IF(S1988<=5%,"Low",IF(S1988<=15%,"Medium","High")) -> Medium | U1988: Credit Card | V1988: On-time | W1988: =IF(V1988="On-time",0,IF('Sales Data'!V1988="Delayed",1,2)) -> 0 | X1988: EMP-119 | Y1988: Elizabeth Thompson | Z1988: VIP | AA1988: 2022 | AB1988: =TEXT(B1988,"mmmm") -> April | AC1988: 4
A1989: ORD-6987 | B1989: 45385 | C1989: CUST-2625 | D1989: Renee Blake | E1989: Retail | F1989: North | G1989: Website | H1989: Beauty | I1989: Shampoo | J1989: 14 | K1989: 532.63 | L1989: 25 | M1989: =J1989*K1989 -> 7456.82 | N1989: =M1989*L1989% -> 1864.205 | O1989: =M1989-N1989 -> 5592.615 | P1989: 227 | Q1989: =P1989*J1989 -> 3178 | R1989: =O1989-Q1989 -> 2414.615 | S1989: =R1989/Q1989 -> 0.75979075 | T1989: =IF(S1989<=5%,"Low",IF(S1989<=15%,"Medium","High")) -> High | U1989: Mobile Wallet | V1989: On-time | W1989: =IF(V1989="On-time",0,IF('Sales Data'!V1989="Delayed",1,2)) -> 0 | X1989: EMP-124 | Y1989: Michael Blankenship | Z1989: New | AA1989: 2024 | AB1989: =TEXT(B1989,"mmmm") -> April | AC1989: 4
A1990: ORD-6988 | B1990: 45386 | C1990: CUST-2751 | D1990: Peter Robinson | E1990: Wholesale | F1990: West | G1990: Website | H1990: Appliances | I1990: Microwave | J1990: 4 | K1990: 1431.95 | L1990: 25 | M1990: =J1990*K1990 -> 5727.8 | N1990: =M1990*L1990% -> 1431.95 | O1990: =M1990-N1990 -> 4295.85 | P1990: 1029.67 | Q1990: =P1990*J1990 -> 4118.68 | R1990: =O1990-Q1990 -> 177.17 | S1990: =R1990/Q1990 -> 0.043016209 | T1990: =IF(S1990<=5%,"Low",IF(S1990<=15%,"Medium","High")) -> Low | U1990: Credit Card | V1990: On-time | W1990: =IF(V1990="On-time",0,IF('Sales Data'!V1990="Delayed",1,2)) -> 0 | X1990: EMP-101 | Y1990: Peter Harris | Z1990: VIP | AA1990: 2024 | AB1990: =TEXT(B1990,"mmmm") -> April | AC1990: 3
A1991: ORD-6989 | B1991: 45387 | C1991: CUST-2293 | D1991: Crystal Marshall | E1991: Wholesale | F1991: North | G1991: Website | H1991: Beauty | I1991: Moisturizer | J1991: 15 | K1991: 1976.09 | L1991: 5 | M1991: =J1991*K1991 -> 29641.35 | N1991: =M1991*L1991% -> 1482.0675 | O1991: =M1991-N1991 -> 28159.282 | P1991: 1126.83 | Q1991: =P1991*J1991 -> 16902.45 | R1991: =O1991-Q1991 -> 11256.833 | S1991: =R1991/Q1991 -> 0.66598821 | T1991: =IF(S1991<=5%,"Low",IF(S1991<=15%,"Medium","High")) -> High | U1991: Debit Card | V1991: On-time | W1991: =IF(V1991="On-time",0,IF('Sales Data'!V1991="Delayed",1,2)) -> 0 | X1991: EMP-129 | Y1991: Jennifer Ramirez | Z1991: New | AA1991: 2024 | AB1991: =TEXT(B1991,"mmmm") -> April | AC1991: 2
A1992: ORD-6990 | B1992: 45388 | C1992: CUST-2794 | D1992: Megan Jones | E1992: Retail | F1992: South | G1992: Store | H1992: Books | I1992: Textbook | J1992: 17 | K1992: 1783.75 | L1992: 0 | M1992: =J1992*K1992 -> 30323.75 | N1992: =M1992*L1992% -> 0 | O1992: =M1992-N1992 -> 30323.75 | P1992: 1253 | Q1992: =P1992*J1992 -> 21301 | R1992: =O1992-Q1992 -> 9022.75 | S1992: =R1992/Q1992 -> 0.4235834 | T1992: =IF(S1992<=5%,"Low",IF(S1992<=15%,"Medium","High")) -> High | U1992: Mobile Wallet | V1992: On-time | W1992: =IF(V1992="On-time",0,IF('Sales Data'!V1992="Delayed",1,2)) -> 0 | X1992: EMP-114 | Y1992: Brent Morrison | Z1992: VIP | AA1992: 2023 | AB1992: =TEXT(B1992,"mmmm") -> April | AC1992: 4
A1993: ORD-6991 | B1993: 45389 | C1993: CUST-1130 | D1993: Lisa Ellis | E1993: Retail | F1993: North | G1993: Store | H1993: Electronics | I1993: Laptop | J1993: 5 | K1993: 544.52 | L1993: 20 | M1993: =J1993*K1993 -> 2722.6 | N1993: =M1993*L1993% -> 544.52 | O1993: =M1993-N1993 -> 2178.08 | P1993: 260.79 | Q1993: =P1993*J1993 -> 1303.95 | R1993: =O1993-Q1993 -> 874.13 | S1993: =R1993/Q1993 -> 0.6703708 | T1993: =IF(S1993<=5%,"Low",IF(S1993<=15%,"Medium","High")) -> High | U1993: Bank Transfer | V1993: On-time | W1993: =IF(V1993="On-time",0,IF('Sales Data'!V1993="Delayed",1,2)) -> 0 | X1993: EMP-129 | Y1993: Jennifer Ramirez | Z1993: VIP | AA1993: 2024 | AB1993: =TEXT(B1993,"mmmm") -> April | AC1993: 2
A1994: ORD-6992 | B1994: 45390 | C1994: CUST-1943 | D1994: Maria Ryan | E1994: Retail | F1994: South | G1994: Website | H1994: Books | I1994: Novel | J1994: 6 | K1994: 1928.29 | L1994: 20 | M1994: =J1994*K1994 -> 11569.74 | N1994: =M1994*L1994% -> 2313.948 | O1994: =M1994-N1994 -> 9255.792 | P1994: 1305.19 | Q1994: =P1994*J1994 -> 7831.14 | R1994: =O1994-Q1994 -> 1424.652 | S1994: =R1994/Q1994 -> 0.18192141 | T1994: =IF(S1994<=5%,"Low",IF(S1994<=15%,"Medium","High")) -> High | U1994: Cash | V1994: On-time | W1994: =IF(V1994="On-time",0,IF('Sales Data'!V1994="Delayed",1,2)) -> 0 | X1994: EMP-102 | Y1994: Lindsey Castaneda | Z1994: New | AA1994: 2024 | AB1994: =TEXT(B1994,"mmmm") -> April | AC1994: 3
A1995: ORD-6993 | B1995: 45391 | C1995: CUST-2488 | D1995: Christina Vasquez | E1995: Online | F1995: North | G1995: Website | H1995: Clothing | I1995: Hat | J1995: 17 | K1995: 776.54 | L1995: 5 | M1995: =J1995*K1995 -> 13201.18 | N1995: =M1995*L1995% -> 660.059 | O1995: =M1995-N1995 -> 12541.121 | P1995: 575.95 | Q1995: =P1995*J1995 -> 9791.15 | R1995: =O1995-Q1995 -> 2749.971 | S1995: =R1995/Q1995 -> 0.28086292 | T1995: =IF(S1995<=5%,"Low",IF(S1995<=15%,"Medium","High")) -> High | U1995: Mobile Wallet | V1995: On-time | W1995: =IF(V1995="On-time",0,IF('Sales Data'!V1995="Delayed",1,2)) -> 0 | X1995: EMP-125 | Y1995: Crystal Schneider | Z1995: Regular | AA1995: 2023 | AB1995: =TEXT(B1995,"mmmm") -> April | AC1995: 2
A1996: ORD-6994 | B1996: 45392 | C1996: CUST-2415 | D1996: Colleen Forbes | E1996: Retail | F1996: North | G1996: Store | H1996: Beauty | I1996: Shampoo | J1996: 20 | K1996: 606.17 | L1996: 5 | M1996: =J1996*K1996 -> 12123.4 | N1996: =M1996*L1996% -> 606.17 | O1996: =M1996-N1996 -> 11517.23 | P1996: 257.43 | Q1996: =P1996*J1996 -> 5148.6 | R1996: =O1996-Q1996 -> 6368.63 | S1996: =R1996/Q1996 -> 1.2369634 | T1996: =IF(S1996<=5%,"Low",IF(S1996<=15%,"Medium","High")) -> High | U1996: Cash | V1996: On-time | W1996: =IF(V1996="On-time",0,IF('Sales Data'!V1996="Delayed",1,2)) -> 0 | X1996: EMP-112 | Y1996: Jeremy Russell | Z1996: New | AA1996: 2025 | AB1996: =TEXT(B1996,"mmmm") -> April | AC1996: 3
... A2001: ORD-6999 | B2001: 45397 | C2001: CUST-1199 | D2001: Anthony Gross | E2001: Retail | F2001: East | G2001: App | H2001: Electronics | I2001: Laptop | J2001: 18 | K2001: 679.24 | L2001: 5 | M2001: =J2001*K2001 -> 12226.32 | N2001: =M2001*L2001% -> 611.316 | O2001: =M2001-N2001 -> 11615.004 | P2001: 279.33 | Q2001: =P2001*J2001 -> 5027.94 | R2001: =O2001-Q2001 -> 6587.064 | S2001: =R2001/Q2001 -> 1.310092 | T2001: =IF(S2001<=5%,"Low",IF(S2001<=15%,"Medium","High")) -> High | U2001: Credit Card | V2001: On-time | W2001: =IF(V2001="On-time",0,IF('Sales Data'!V2001="Delayed",1,2)) -> 0 | X2001: EMP-107 | Y2001: Lauren Barnes | Z2001: Regular | AA2001: 2023 | AB2001: =TEXT(B2001,"mmmm") -> April | AC2001: 3

Sheet Working Sheet
B1: Market Sales Analyze By Different Parameters
B8: Customers RFM | G8: Region Wise Sales
B10: Customer ID | C10: Recency (Days) | D10: Frequency | E10: Monetary | G10: Sr No# | H10: Region | I10: Total Sales | J10: Total Profit | K10: Average Order Value
B11: CUST-1000 | C11: 320 | D11: 2 | E11: 11324.28 | G11: 1 | H11: South | I11: 5713717.6 | J11: 1482869.2 | K11: 10.620553
B12: CUST-1002 | C12: 390 | D12: 3 | E12: 45313.52 | G12: =1+G11 -> 2 | H12: North | I12: 5982431.5 | J12: 1491330.5 | K12: 10.709611
B13: CUST-1003 | C13: 605 | D13: 4 | E13: 46198.53 | G13: =1+G12 -> 3 | H13: East | I13: 5536758.2 | J13: 1551929.2 | K13: 10.83871
B14: CUST-1008 | C14: 440 | D14: 2 | E14: 12126.72 | G14: =1+G13 -> 4 | H14: West | I14: 5526799.5 | J14: 1571288 | K14: 10.541339
B15: CUST-1010 | C15: 477 | D15: 2 | E15: 33506.24 | G15: Product Wise Sales
B16: CUST-1011 | C16: 184 | D16: 2 | E16: 35180
B17: CUST-1012 | C17: 303 | D17: 2 | E17: 3994.92 | G17: Sr No# | H17: Product Category | I17: Total Sales | J17: Total Profit | K17: Average Order Value
B18: CUST-1013 | C18: 440 | D18: 3 | E18: 61609.61 | G18: 1 | H18: Electronics | I18: 2310125 | J18: 180698.06 | K18: 15.653595
B19: CUST-1015 | C19: 55 | D19: 1 | E19: 5540.64 | G19: =1+G18 -> 2 | H19: Clothing | I19: 2840205.9 | J19: 162408.89 | K19: 14.606061
B20: CUST-1016 | C20: 698 | D20: 1 | E20: 19792.62 | G20: =1+G19 -> 3 | H20: Furniture | I20: 2840566.4 | J20: 65522.922 | K20: 14.970674
B21: CUST-1018 | C21: 25 | D21: 1 | E21: 4943.98 | G21: =1+G20 -> 4 | H21: Beauty | I21: 2724862.1 | J21: 101905.3 | K21: 15.897833
B22: CUST-1020 | C22: 706 | D22: 1 | E22: 2034.2 | G22: =1+G21 -> 5 | H22: Appliances | I22: 2764402.9 | J22: 102970.99 | K22: 15.521127
B23: CUST-1022 | C23: 576 | D23: 1 | E23: 23375.69 | G23: =1+G22 -> 6 | H23: Books | I23: 2906435.8 | J23: 103453.25 | K23: 15.37092
B24: CUST-1024 | C24: 277 | D24: 1 | E24: 4638.79 | G24: Sales Channel Wise Sales
B25: CUST-1025 | C25: 602 | D25: 1 | E25: 9679.1
B26: CUST-1026 | C26: 168 | D26: 2 | E26: 7594.72 | G26: Sr No# | H26: Sales Channel | I26: Total Sales | J26: Total Profit | K26: Average Order Value
B27: CUST-1027 | C27: 501 | D27: 2 | E27: 9578 | G27: 1 | H27: Store | I27: 375231.81 | J27: 210.18616 | K27: 1224.2672
B28: CUST-1033 | C28: 558 | D28: 2 | E28: 19395.24 | G28: =1+G27 -> 2 | H28: App | I28: 313028.14 | J28: 177.34337 | K28: 1245.3394
B29: CUST-1035 | C29: 590 | D29: 1 | E29: 957.32 | G29: =1+G28 -> 3 | H29: Website | I29: 701251.74 | J29: 368.43789 | K29: 1233.4024
B30: CUST-1036 | C30: 107 | D30: 2 | E30: 18145.71 | G30: Product Wise Order and Performance
B31: CUST-1037 | C31: 321 | D31: 1 | E31: 37900.2
B32: CUST-1038 | C32: 385 | D32: 1 | E32: 31696.73 | G32: Sr No# | H32: Product Category | I32: Total Orders | J32: Return orders | K32: Return Rate
B33: CUST-1039 | C33: 939 | D33: 1 | E33: 1046.51 | G33: 1 | H33: Electronics | I33: 307 | J33: 13 | K33: 0.042345277
B34: CUST-1041 | C34: 284 | D34: 3 | E34: 42081.93 | G34: =1+G33 -> 2 | H34: Clothing | I34: 330 | J34: 17 | K34: 0.051515152
B35: CUST-1042 | C35: 812 | D35: 2 | E35: 19198.76 | G35: =1+G34 -> 3 | H35: Furniture | I35: 342 | J35: 20 | K35: 0.058479532
B36: CUST-1043 | C36: 358 | D36: 1 | E36: 28366.02 | G36: =1+G35 -> 4 | H36: Beauty | I36: 326 | J36: 12 | K36: 0.036809816
B37: CUST-1044 | C37: 73 | D37: 1 | E37: 19063.92 | G37: =1+G36 -> 5 | H37: Appliances | I37: 356 | J37: 16 | K37: 0.04494382
B38: CUST-1045 | C38: 375 | D38: 2 | E38: 44965.95 | G38: =1+G37 -> 6 | H38: Books | I38: 339 | J38: 10 | K38: 0.029498525
B39: CUST-1046 | C39: 829 | D39: 1 | E39: 4445.74 | G39: Top 20 Customers
B40: CUST-1049 | C40: 745 | D40: 2 | E40: 40928.85
B41: CUST-1053 | C41: 977 | D41: 1 | E41: 29546.64 | G41: Sr No# | H41: Customer Id | I41: ID | J41: Customer Name | K41: Region | L41: Total Sales
B42: CUST-1054 | C42: 179 | D42: 1 | E42: 11334.9 | G42: 1 | H42: CUST-1276 | I42: 1276 | J42: Nicole Wheeler | K42: West | L42: 120861.11
B43: CUST-1057 | C43: 440 | D43: 1 | E43: 18991.89 | G43: 2 | H43: CUST-2415 | I43: 2415 | J43: Jerry Rodriguez | K43: North | L43: 107835.22
B44: CUST-1060 | C44: 151 | D44: 3 | E44: 50151.96 | G44: 3 | H44: CUST-1245 | I44: 1245 | J44: James Bonilla | K44: South | L44: 97495.6
B45: CUST-1061 | C45: 275 | D45: 1 | E45: 20381.9 | G45: 4 | H45: CUST-1271 | I45: 1271 | J45: Jennifer Walker | K45: North | L45: 96990.02
B46: CUST-1065 | C46: 349 | D46: 2 | E46: 32968.22 | G46: 5 | H46: CUST-1519 | I46: 1519 | J46: Cory Smith | K46: West | L46: 95286.31
B47: CUST-1066 | C47: 474 | D47: 1 | E47: 2450 | G47: 6 | H47: CUST-2381 | I47: 2381 | J47: Jessica Macdonald | K47: East | L47: 90305.29
...

Sheet Project Calculation
B3: Region | C3: Total Sales | D3: Total Profit | E3: Average Order Value
B4: South | C4: =SUMIF('Sales Data'!F2:$AC$2001,'Project Calculation'!B4,'Sales Data'!$O:$O) -> 5713717.6 | D4: =SUMIF('Sales Data'!$F$2:$R$2001,'Project Calculation'!B4,'Sales Data'!$R$2:$R$2001) -> 1482869.2 | E4: =AVERAGEIF('Sales Data'!$F$2:$AC$2001,'Project Calculation'!B4,'Sales Data'!J2:J2001) -> 10.620553
B5: North | C5: =SUMIF('Sales Data'!F3:$AC$2001,'Project Calculation'!B5,'Sales Data'!$O:$O) -> 5982431.5 | D5: =SUMIF('Sales Data'!$F$2:$R$2001,'Project Calculation'!B5,'Sales Data'!$R$2:$R$2001) -> 1491330.5 | E5: =AVERAGEIF('Sales Data'!$F$2:$AC$2001,'Project Calculation'!B5,'Sales Data'!J3:J2001) -> 10.709611
B6: East | C6: =SUMIF('Sales Data'!F4:$AC$2001,'Project Calculation'!B6,'Sales Data'!$O:$O) -> 5536758.2 | D6: =SUMIF('Sales Data'!$F$2:$R$2001,'Project Calculation'!B6,'Sales Data'!$R$2:$R$2001) -> 1551929.2 | E6: =AVERAGEIF('Sales Data'!$F$2:$AC$2001,'Project Calculation'!B6,'Sales Data'!J4:J2002) -> 10.83871
B7: West | C7: =SUMIF('Sales Data'!F5:$AC$2001,'Project Calculation'!B7,'Sales Data'!$O:$O) -> 5526799.5 | D7: =SUMIF('Sales Data'!$F$2:$R$2001,'Project Calculation'!B7,'Sales Data'!$R$2:$R$2001) -> 1571288 | E7: =AVERAGEIF('Sales Data'!$F$2:$AC$2001,'Project Calculation'!B7,'Sales Data'!J5:J2003) -> 10.541339
B10: Product Category | C10: Total Sales | D10: Total Profit | E10: Average Order Value
B11: Electronics | C11: =SUMIF('Sales Data'!F7:$AC$2001,'Project Calculation'!B11,'Sales Data'!$O:$O) -> 2310125 | D11: =SUMIF('Sales Data'!$H$1763:$AC$2001,'Project Calculation'!B11,'Sales Data'!$R$2:$R$2001) -> 180698.06 | E11: =AVERAGEIF('Sales Data'!$F$2:$AC$2001,'Project Calculation'!B11,'Sales Data'!J7:J2005) -> 15.653595
B12: Clothing | C12: =SUMIF('Sales Data'!F8:$AC$2001,'Project Calculation'!B12,'Sales Data'!$O:$O) -> 2840205.9 | D12: =SUMIF('Sales Data'!$H$1763:$AC$2001,'Project Calculation'!B12,'Sales Data'!$R$2:$R$2001) -> 162408.89 | E12: =AVERAGEIF('Sales Data'!$F$2:$AC$2001,'Project Calculation'!B12,'Sales Data'!J8:J2006) -> 14.606061
B13: Furniture | C13: =SUMIF('Sales Data'!F9:$AC$2001,'Project Calculation'!B13,'Sales Data'!$O:$O) -> 2840566.4 | D13: =SUMIF('Sales Data'!$H$1763:$AC$2001,'Project Calculation'!B13,'Sales Data'!$R$2:$R$2001) -> 65522.922 | E13: =AVERAGEIF('Sales Data'!$F$2:$AC$2001,'Project Calculation'!B13,'Sales Data'!J9:J2007) -> 14.970674
B14: Beauty | C14: =SUMIF('Sales Data'!F10:$AC$2001,'Project Calculation'!B14,'Sales Data'!$O:$O) -> 2724862.1 | D14: =SUMIF('Sales Data'!$H$1763:$AC$2001,'Project Calculation'!B14,'Sales Data'!$R$2:$R$2001) -> 101905.3 | E14: =AVERAGEIF('Sales Data'!$F$2:$AC$2001,'Project Calculation'!B14,'Sales Data'!J10:J2008) -> 15.897833
B15: Appliances | C15: =SUMIF('Sales Data'!F11:$AC$2001,'Project Calculation'!B15,'Sales Data'!$O:$O) -> 2764402.9 | D15: =SUMIF('Sales Data'!$H$1763:$AC$2001,'Project Calculation'!B15,'Sales Data'!$R$2:$R$2001) -> 102970.99 | E15: =AVERAGEIF('Sales Data'!$F$2:$AC$2001,'Project Calculation'!B15,'Sales Data'!J11:J2009) -> 15.521127
B16: Books | C16: =SUMIF('Sales Data'!F12:$AC$2001,'Project Calculation'!B16,'Sales Data'!$O:$O) -> 2906435.8 | D16: =SUMIF('Sales Data'!$H$1763:$AC$2001,'Project Calculation'!B16,'Sales Data'!$R$2:$R$2001) -> 103453.25 | E16: =AVERAGEIF('Sales Data'!$F$2:$AC$2001,'Project Calculation'!B16,'Sales Data'!J12:J2010) -> 15.37092
B19: Sales Channel | C19: Total Sales | D19: Total Profit | E19: Average Order Value
B20: Store | C20: =SUMIF('Sales Data'!F14:$AC$2001,'Project Calculation'!B20,'Sales Data'!$O:$O) -> 375231.81 | D20: =SUMIF('Sales Data'!$F$2:$R$2001,'Project Calculation'!B20,'Sales Data'!$R$2:$R$2001) -> 210.18616 | E20: =AVERAGEIF('Sales Data'!$F$2:$AC$2001,'Project Calculation'!B20,'Sales Data'!J14:J2012) -> 1224.2672
B21: App | C21: =SUMIF('Sales Data'!F15:$AC$2001,'Project Calculation'!B21,'Sales Data'!$O:$O) -> 313028.14 | D21: =SUMIF('Sales Data'!$F$2:$R$2001,'Project Calculation'!B21,'Sales Data'!$R$2:$R$2001) -> 177.34337 | E21: =AVERAGEIF('Sales Data'!$F$2:$AC$2001,'Project Calculation'!B21,'Sales Data'!J15:J2013) -> 1245.3394
B22: Website | C22: =SUMIF('Sales Data'!F16:$AC$2001,'Project Calculation'!B22,'Sales Data'!$O:$O) -> 701251.74 | D22: =SUMIF('Sales Data'!$F$2:$R$2001,'Project Calculation'!B22,'Sales Data'!$R$2:$R$2001) -> 368.43789 | E22: =AVERAGEIF('Sales Data'!$F$2:$AC$2001,'Project Calculation'!B22,'Sales Data'!J16:J2014) -> 1233.4024
B25: Product Category | C25: Total Orders | D25: Return orders | E25: Return Rate
B26: Electronics | C26: =COUNTIF('Sales Data'!$H$2:$H$2001,'Project Calculation'!B26) -> 307 | D26: =COUNTIFS('Sales Data'!$H$2:$H$2001,'Project Calculation'!B26,'Sales Data'!$V$2:$V$2001,"Returned") -> 13 | E26: =D26/C26 -> 0.042345277
B27: Clothing | C27: =COUNTIF('Sales Data'!$H$2:$H$2001,'Project Calculation'!B27) -> 330 | D27: =COUNTIFS('Sales Data'!$H$2:$H$2001,'Project Calculation'!B27,'Sales Data'!$V$2:$V$2001,"Returned") -> 17 | E27: =D27/C27 -> 0.051515152
B28: Furniture | C28: =COUNTIF('Sales Data'!$H$2:$H$2001,'Project Calculation'!B28) -> 342 | D28: =COUNTIFS('Sales Data'!$H$2:$H$2001,'Project Calculation'!B28,'Sales Data'!$V$2:$V$2001,"Returned") -> 20 | E28: =D28/C28 -> 0.058479532
B29: Beauty | C29: =COUNTIF('Sales Data'!$H$2:$H$2001,'Project Calculation'!B29) -> 326 | D29: =COUNTIFS('Sales Data'!$H$2:$H$2001,'Project Calculation'!B29,'Sales Data'!$V$2:$V$2001,"Returned") -> 12 | E29: =D29/C29 -> 0.036809816
B30: Appliances | C30: =COUNTIF('Sales Data'!$H$2:$H$2001,'Project Calculation'!B30) -> 356 | D30: =COUNTIFS('Sales Data'!$H$2:$H$2001,'Project Calculation'!B30,'Sales Data'!$V$2:$V$2001,"Returned") -> 16 | E30: =D30/C30 -> 0.04494382
B31: Books | C31: =COUNTIF('Sales Data'!$H$2:$H$2001,'Project Calculation'!B31) -> 339 | D31: =COUNTIFS('Sales Data'!$H$2:$H$2001,'Project Calculation'!B31,'Sales Data'!$V$2:$V$2001,"Returned") -> 10 | E31: =D31/C31 -> 0.029498525
B34: Sr No# | C34: Customer Id | D34: ID | E34: Customer Name | F34: Region | G34: Total Sales
B35: 1 | C35: =VLOOKUP(G35,CHOOSE({1,2},RFM!F3:F1280,RFM!A3:A1280),2,0) -> CUST-1276 | D35: =RIGHT(C35,4) -> 1276 | E35: =VLOOKUP(C35,'Sales Data'!$C$2:$AC$2001,2,0) -> Nicole Wheeler | F35: =VLOOKUP(C35,'Sales Data'!$C$2:$AC$2001,4,0) -> West | G35: =LARGE(RFM!F3:F1280,B35) -> 120861.11
B36: 2 | C36: =VLOOKUP(G36,CHOOSE({1,2},RFM!F4:F1281,RFM!A4:A1281),2,0) -> CUST-2415 | D36: =RIGHT(C36,4) -> 2415 | E36: =VLOOKUP(C36,'Sales Data'!$C$2:$AC$2001,2,0) -> Jerry Rodriguez | F36: =VLOOKUP(C36,'Sales Data'!$C$2:$AC$2001,4,0) -> North | G36: =LARGE(RFM!F4:F1281,B36) -> 107835.22
B37: 3 | C37: =VLOOKUP(G37,CHOOSE({1,2},RFM!F5:F1282,RFM!A5:A1282),2,0) -> CUST-1245 | D37: =RIGHT(C37,4) -> 1245 | E37: =VLOOKUP(C37,'Sales Data'!$C$2:$AC$2001,2,0) -> James Bonilla | F37: =VLOOKUP(C37,'Sales Data'!$C$2:$AC$2001,4,0) -> South | G37: =LARGE(RFM!F5:F1282,B37) -> 97495.6
B38: 4 | C38: =VLOOKUP(G38,CHOOSE({1,2},RFM!F6:F1283,RFM!A6:A1283),2,0) -> CUST-1271 | D38: =RIGHT(C38,4) -> 1271 | E38: =VLOOKUP(C38,'Sales Data'!$C$2:$AC$2001,2,0) -> Jennifer Walker | F38: =VLOOKUP(C38,'Sales Data'!$C$2:$AC$2001,4,0) -> North | G38: =LARGE(RFM!F6:F1283,B38) -> 96990.02
B39: 5 | C39: =VLOOKUP(G39,CHOOSE({1,2},RFM!F7:F1284,RFM!A7:A1284),2,0) -> CUST-1519 | D39: =RIGHT(C39,4) -> 1519 | E39: =VLOOKUP(C39,'Sales Data'!$C$2:$AC$2001,2,0) -> Cory Smith | F39: =VLOOKUP(C39,'Sales Data'!$C$2:$AC$2001,4,0) -> West | G39: =LARGE(RFM!F7:F1284,B39) -> 95286.31
B40: 6 | C40: =VLOOKUP(G40,CHOOSE({1,2},RFM!F8:F1285,RFM!A8:A1285),2,0) -> CUST-2381 | D40: =RIGHT(C40,4) -> 2381 | E40: =VLOOKUP(C40,'Sales Data'!$C$2:$AC$2001,2,0) -> Jessica Macdonald | F40: =VLOOKUP(C40,'Sales Data'!$C$2:$AC$2001,4,0) -> East | G40: =LARGE(RFM!F8:F1285,B40) -> 90305.29
B41: 7 | C41: =VLOOKUP(G41,CHOOSE({1,2},RFM!F9:F1286,RFM!A9:A1286),2,0) -> CUST-2251 | D41: =RIGHT(C41,4) -> 2251 | E41: =VLOOKUP(C41,'Sales Data'!$C$2:$AC$2001,2,0) -> James Roman | F41: =VLOOKUP(C41,'Sales Data'!$C$2:$AC$2001,4,0) -> West | G41: =LARGE(RFM!F9:F1286,B41) -> 85871.72
B42: 8 | C42: =VLOOKUP(G42,CHOOSE({1,2},RFM!F10:F1287,RFM!A10:A1287),2,0) -> CUST-1665 | D42: =RIGHT(C42,4) -> 1665 | E42: =VLOOKUP(C42,'Sales Data'!$C$2:$AC$2001,2,0) -> Erika Knight | F42: =VLOOKUP(C42,'Sales Data'!$C$2:$AC$2001,4,0) -> North | G42: =LARGE(RFM!F10:F1287,B42) -> 83542.58
B43: 9 | C43: =VLOOKUP(G43,CHOOSE({1,2},RFM!F11:F1288,RFM!A11:A1288),2,0) -> CUST-1378 | D43: =RIGHT(C43,4) -> 1378 | E43: =VLOOKUP(C43,'Sales Data'!$C$2:$AC$2001,2,0) -> Laura Moore | F43: =VLOOKUP(C43,'Sales Data'!$C$2:$AC$2001,4,0) -> North | G43: =LARGE(RFM!F11:F1288,B43) -> 82329.96
B44: 10 | C44: =VLOOKUP(G44,CHOOSE({1,2},RFM!F12:F1289,RFM!A12:A1289),2,0) -> CUST-2876 | D44: =RIGHT(C44,4) -> 2876 | E44: =VLOOKUP(C44,'Sales Data'!$C$2:$AC$2001,2,0) -> Wesley Le | F44: =VLOOKUP(C44,'Sales Data'!$C$2:$AC$2001,4,0) -> West | G44: =LARGE(RFM!F12:F1289,B44) -> 81620.82
B45: =1+B44 -> 11 | C45: =VLOOKUP(G45,CHOOSE({1,2},RFM!F13:F1290,RFM!A13:A1290),2,0) -> CUST-2701 | D45: =RIGHT(C45,4) -> 2701 | E45: =VLOOKUP(C45,'Sales Data'!$C$2:$AC$2001,2,0) -> Erica Yates | F45: =VLOOKUP(C45,'Sales Data'!$C$2:$AC$2001,4,0) -> West | G45: =LARGE(RFM!F13:F1290,B45) -> 79643.05
B46: =1+B45 -> 12 | C46: =VLOOKUP(G46,CHOOSE({1,2},RFM!F14:F1291,RFM!A14:A1291),2,0) -> CUST-1348 | D46: =RIGHT(C46,4) -> 1348 | E46: =VLOOKUP(C46,'Sales Data'!$C$2:$AC$2001,2,0) -> Jennifer Paul | F46: =VLOOKUP(C46,'Sales Data'!$C$2:$AC$2001,4,0) -> West | G46: =LARGE(RFM!F14:F1291,B46) -> 79585.72
B47: =1+B46 -> 13 | C47: =VLOOKUP(G47,CHOOSE({1,2},RFM!F15:F1292,RFM!A15:A1292),2,0) -> CUST-2271 | D47: =RIGHT(C47,4) -> 2271 | E47: =VLOOKUP(C47,'Sales Data'!$C$2:$AC$2001,2,0) -> Henry Beasley | F47: =VLOOKUP(C47,'Sales Data'!$C$2:$AC$2001,4,0) -> North | G47: =LARGE(RFM!F15:F1292,B47) -> 78163.43
B48: =1+B47 -> 14 | C48: =VLOOKUP(G48,CHOOSE({1,2},RFM!F16:F1293,RFM!A16:A1293),2,0) -> CUST-1240 | D48: =RIGHT(C48,4) -> 1240 | E48: =VLOOKUP(C48,'Sales Data'!$C$2:$AC$2001,2,0) -> Mark Mcdonald | F48: =VLOOKUP(C48,'Sales Data'!$C$2:$AC$2001,4,0) -> South | G48: =LARGE(RFM!F16:F1293,B48) -> 76935.08
B49: =1+B48 -> 15 | C49: =VLOOKUP(G49,CHOOSE({1,2},RFM!F17:F1294,RFM!A17:A1294),2,0) -> CUST-1200 | D49: =RIGHT(C49,4) -> 1200 | E49: =VLOOKUP(C49,'Sales Data'!$C$2:$AC$2001,2,0) -> Jared Jones | F49: =VLOOKUP(C49,'Sales Data'!$C$2:$AC$2001,4,0) -> East | G49: =LARGE(RFM!F17:F1294,B49) -> 73582.66
B50: =1+B49 -> 16 | C50: =VLOOKUP(G50,CHOOSE({1,2},RFM!F18:F1295,RFM!A18:A1295),2,0) -> CUST-1410 | D50: =RIGHT(C50,4) -> 1410 | E50: =VLOOKUP(C50,'Sales Data'!$C$2:$AC$2001,2,0) -> Phillip Stuart | F50: =VLOOKUP(C50,'Sales Data'!$C$2:$AC$2001,4,0) -> North | G50: =LARGE(RFM!F18:F1295,B50) -> 73560.51
...

Sheet RFM
B1: 45924
A2: Customer ID | B2: Recency (days) | D2: Recency (Days) | E2: Frequency | F2: Monetary
A3: CUST-1000 | B3: 319 | C3: =_xlfn.MAXIFS('Sales Data'!B:B,'Sales Data'!C:C,RFM!A3) -> 45604 | D3: =DATEDIF(C3,$B$1,"D") -> 320 | E3: =COUNTIF('Sales Data'!$C$2:$C$2001,RFM!A3) -> 2 | F3: =SUMIF('Sales Data'!$C$2:$M$2001,RFM!A3,'Sales Data'!$M$2:$M$2001) -> 11324.28
A4: CUST-1002 | B4: 389 | C4: =_xlfn.MAXIFS('Sales Data'!B:B,'Sales Data'!C:C,RFM!A4) -> 45534 | D4: =DATEDIF(C4,$B$1,"D") -> 390 | E4: =COUNTIF('Sales Data'!$C$2:$C$2001,RFM!A4) -> 3 | F4: =SUMIF('Sales Data'!$C$2:$M$2001,RFM!A4,'Sales Data'!$M$2:$M$2001) -> 45313.52
A5: CUST-1003 | B5: 604 | C5: =_xlfn.MAXIFS('Sales Data'!B:B,'Sales Data'!C:C,RFM!A5) -> 45319 | D5: =DATEDIF(C5,$B$1,"D") -> 605 | E5: =COUNTIF('Sales Data'!$C$2:$C$2001,RFM!A5) -> 4 | F5: =SUMIF('Sales Data'!$C$2:$M$2001,RFM!A5,'Sales Data'!$M$2:$M$2001) -> 46198.53
A6: CUST-1008 | B6: 439 | C6: =_xlfn.MAXIFS('Sales Data'!B:B,'Sales Data'!C:C,RFM!A6) -> 45484 | D6: =DATEDIF(C6,$B$1,"D") -> 440 | E6: =COUNTIF('Sales Data'!$C$2:$C$2001,RFM!A6) -> 2 | F6: =SUMIF('Sales Data'!$C$2:$M$2001,RFM!A6,'Sales Data'!$M$2:$M$2001) -> 12126.72
A7: CUST-1010 | B7: 476 | C7: =_xlfn.MAXIFS('Sales Data'!B:B,'Sales Data'!C:C,RFM!A7) -> 45447 | D7: =DATEDIF(C7,$B$1,"D") -> 477 | E7: =COUNTIF('Sales Data'!$C$2:$C$2001,RFM!A7) -> 2 | F7: =SUMIF('Sales Data'!$C$2:$M$2001,RFM!A7,'Sales Data'!$M$2:$M$2001) -> 33506.24
A8: CUST-1011 | B8: 183 | C8: =_xlfn.MAXIFS('Sales Data'!B:B,'Sales Data'!C:C,RFM!A8) -> 45740 | D8: =DATEDIF(C8,$B$1,"D") -> 184 | E8: =COUNTIF('Sales Data'!$C$2:$C$2001,RFM!A8) -> 2 | F8: =SUMIF('Sales Data'!$C$2:$M$2001,RFM!A8,'Sales Data'!$M$2:$M$2001) -> 35180
A9: CUST-1012 | B9: 302 | C9: =_xlfn.MAXIFS('Sales Data'!B:B,'Sales Data'!C:C,RFM!A9) -> 45621 | D9: =DATEDIF(C9,$B$1,"D") -> 303 | E9: =COUNTIF('Sales Data'!$C$2:$C$2001,RFM!A9) -> 2 | F9: =SUMIF('Sales Data'!$C$2:$M$2001,RFM!A9,'Sales Data'!$M$2:$M$2001) -> 3994.92
A10: CUST-1013 | B10: 439 | C10: =_xlfn.MAXIFS('Sales Data'!B:B,'Sales Data'!C:C,RFM!A10) -> 45484 | D10: =DATEDIF(C10,$B$1,"D") -> 440 | E10: =COUNTIF('Sales Data'!$C$2:$C$2001,RFM!A10) -> 3 | F10: =SUMIF('Sales Data'!$C$2:$M$2001,RFM!A10,'Sales Data'!$M$2:$M$2001) -> 61609.61
A11: CUST-1015 | B11: 54 | C11: =_xlfn.MAXIFS('Sales Data'!B:B,'Sales Data'!C:C,RFM!A11) -> 45869 | D11: =DATEDIF(C11,$B$1,"D") -> 55 | E11: =COUNTIF('Sales Data'!$C$2:$C$2001,RFM!A11) -> 1 | F11: =SUMIF('Sales Data'!$C$2:$M$2001,RFM!A11,'Sales Data'!$M$2:$M$2001) -> 5540.64
A12: CUST-1016 | B12: 697 | C12: =_xlfn.MAXIFS('Sales Data'!B:B,'Sales Data'!C:C,RFM!A12) -> 45226 | D12: =DATEDIF(C12,$B$1,"D") -> 698 | E12: =COUNTIF('Sales Data'!$C$2:$C$2001,RFM!A12) -> 1 | F12: =SUMIF('Sales Data'!$C$2:$M$2001,RFM!A12,'Sales Data'!$M$2:$M$2001) -> 19792.62
A13: CUST-1018 | B13: 24 | C13: =_xlfn.MAXIFS('Sales Data'!B:B,'Sales Data'!C:C,RFM!A13) -> 45899 | D13: =DATEDIF(C13,$B$1,"D") -> 25 | E13: =COUNTIF('Sales Data'!$C$2:$C$2001,RFM!A13) -> 1 | F13: =SUMIF('Sales Data'!$C$2:$M$2001,RFM!A13,'Sales Data'!$M$2:$M$2001) -> 4943.98
A14: CUST-1020 | B14: 705 | C14: =_xlfn.MAXIFS('Sales Data'!B:B,'Sales Data'!C:C,RFM!A14) -> 45218 | D14: =DATEDIF(C14,$B$1,"D") -> 706 | E14: =COUNTIF('Sales Data'!$C$2:$C$2001,RFM!A14) -> 1 | F14: =SUMIF('Sales Data'!$C$2:$M$2001,RFM!A14,'Sales Data'!$M$2:$M$2001) -> 2034.2
... A1280: CUST-2999 | B1280: 925 | C1280: =_xlfn.MAXIFS('Sales Data'!B:B,'Sales Data'!C:C,RFM!A1280) -> 44998 | D1280: =DATEDIF(C1280,$B$1,"D") -> 926 | E1280: =COUNTIF('Sales Data'!$C$2:$C$2001,RFM!A1280) -> 1 | F1280: =SUMIF('Sales Data'!$C$2:$M$2001,RFM!A1280,'Sales Data'!$M$2:$M$2001) -> 13362.9
